Workbook

Sheet raw_data
A1: OLD_DATE | B1: date | C1: merchant | D1: amount | E1: original_category | F1: my_category | G1: source | H1: notes
A2: 45694 | B2: =TEXT(A2,"yyyy-mm") -> 2025-02 | C2: JOHNNY DELMONICO'S | D2: 434.92 | E2: Restaurants | F2: {=IFERROR( INDEX(lookup_table!B:B, MATCH(TRUE, ISNUMBER(SEARCH(lookup_table!A:A,C2)), 0) ), "Uncategorized")} -> Dining Out | G2: Card1
A3: 45666 | B3: =TEXT(A3,"yyyy-mm") -> 2025-01 | C3: KWIK TRIP | D3: 8.31 | E3: Gas / Fuel | F3: {=IFERROR( INDEX(lookup_table!B:B, MATCH(TRUE, ISNUMBER(SEARCH(lookup_table!A:A,C3)), 0) ), "Uncategorized")} -> Transportation | G3: Bank2
A4: 45668 | B4: =TEXT(A4,"yyyy-mm") -> 2025-01 | C4: TARGET | D4: 6.33 | E4: Shopping | F4: {=IFERROR( INDEX(lookup_table!B:B, MATCH(TRUE, ISNUMBER(SEARCH(lookup_table!A:A,C4)), 0) ), "Uncategorized")} -> Groceries | G4: Bank2
A5: 45674 | B5: =TEXT(A5,"yyyy-mm") -> 2025-01 | C5: HAWKS BAR AND GRILL | D5: 5.16 | E5: Dining Out | F5: {=IFERROR( INDEX(lookup_table!B:B, MATCH(TRUE, ISNUMBER(SEARCH(lookup_table!A:A,C5)), 0) ), "Uncategorized")} -> Dining Out | G5: Bank2
A6: 45675 | B6: =TEXT(A6,"yyyy-mm") -> 2025-01 | C6: KWIK TRIP | D6: 5.93 | E6: Gas / Fuel | F6: {=IFERROR( INDEX(lookup_table!B:B, MATCH(TRUE, ISNUMBER(SEARCH(lookup_table!A:A,C6)), 0) ), "Uncategorized")} -> Transportation | G6: Bank2
A7: 45675 | B7: =TEXT(A7,"yyyy-mm") -> 2025-01 | C7: KWIK TRIP | D7: 4.21 | E7: Gas / Fuel | F7: {=IFERROR( INDEX(lookup_table!B:B, MATCH(TRUE, ISNUMBER(SEARCH(lookup_table!A:A,C7)), 0) ), "Uncategorized")} -> Transportation | G7: Bank2
A8: 45676 | B8: =TEXT(A8,"yyyy-mm") -> 2025-01 | C8: CANTEEN VENDING LAC | D8: 2.25 | E8: Dining Out | F8: {=IFERROR( INDEX(lookup_table!B:B, MATCH(TRUE, ISNUMBER(SEARCH(lookup_table!A:A,C8)), 0) ), "Uncategorized")} -> Other | G8: Bank2
A9: 45681 | B9: =TEXT(A9,"yyyy-mm") -> 2025-01 | C9: BP | D9: 6.52 | E9: Gas / Fuel | F9: {=IFERROR( INDEX(lookup_table!B:B, MATCH(TRUE, ISNUMBER(SEARCH(lookup_table!A:A,C9)), 0) ), "Uncategorized")} -> Transportation | G9: Bank2
A10: 45690 | B10: =TEXT(A10,"yyyy-mm") -> 2025-02 | C10: STARBUCKS | D10: 16.13 | E10: Restaurants | F10: {=IFERROR( INDEX(lookup_table!B:B, MATCH(TRUE, ISNUMBER(SEARCH(lookup_table!A:A,C10)), 0) ), "Uncategorized")} -> Dining Out | G10: Card2
A11: 45690 | B11: =TEXT(A11,"yyyy-mm") -> 2025-02 | C11: WALMART | D11: 74.42 | E11: Grocery | F11: {=IFERROR( INDEX(lookup_table!B:B, MATCH(TRUE, ISNUMBER(SEARCH(lookup_table!A:A,C11)), 0) ), "Uncategorized")} -> Groceries | G11: Card1
A12: 45690 | B12: =TEXT(A12,"yyyy-mm") -> 2025-02 | C12: AMAZON MKTPL | D12: 9.08 | E12: Merchandise | F12: {=IFERROR( INDEX(lookup_table!B:B, MATCH(TRUE, ISNUMBER(SEARCH(lookup_table!A:A,C12)), 0) ), "Uncategorized")} -> Shopping | G12: Card2
A13: 45690 | B13: =TEXT(A13,"yyyy-mm") -> 2025-02 | C13: KWIK TRIP | D13: 43.57 | E13: Gas | F13: {=IFERROR( INDEX(lookup_table!B:B, MATCH(TRUE, ISNUMBER(SEARCH(lookup_table!A:A,C13)), 0) ), "Uncategorized")} -> Transportation | G13: Card1
... A436: 45894 | B436: =TEXT(A436,"yyyy-mm") -> 2025-08 | C436: PARAMOUNT+ | D436: 4.74 | E436: Utilities | F436: {=IFERROR( INDEX(lookup_table!B:B, MATCH(TRUE, ISNUMBER(SEARCH(lookup_table!A:A,C436)), 0) ), "Uncategorized")} -> Subscriptions | G436: Card1
A437: 45894 | B437: =TEXT(A437,"yyyy-mm") -> 2025-08 | C437: 76 | D437: 15.12 | E437: Gas | F437: {=IFERROR( INDEX(lookup_table!B:B, MATCH(TRUE, ISNUMBER(SEARCH(lookup_table!A:A,C437)), 0) ), "Uncategorized")} -> Transportation | G437: Card1
A438: 45894 | B438: =TEXT(A438,"yyyy-mm") -> 2025-08 | C438: ASHFORD VALLEY STATE ROUTE US ASHFORD WA | D438: 4.99 | E438: Uncategorized | F438: {=IFERROR( INDEX(lookup_table!B:B, MATCH(TRUE, ISNUMBER(SEARCH(lookup_table!A:A,C438)), 0) ), "Uncategorized")} -> Transportation | G438: Bank2
A439: 45894 | B439: =TEXT(A439,"yyyy-mm") -> 2025-08 | C439: JACKSON VISITOR CENTER | D439: 11.88 | E439: Other | F439: {=IFERROR( INDEX(lookup_table!B:B, MATCH(TRUE, ISNUMBER(SEARCH(lookup_table!A:A,C439)), 0) ), "Uncategorized")} -> Travel | G439: Card1
A440: 45895 | B440: =TEXT(A440,"yyyy-mm") -> 2025-08 | C440: YAMATO SUSHI | D440: 23.2 | E440: Transportation | F440: {=IFERROR( INDEX(lookup_table!B:B, MATCH(TRUE, ISNUMBER(SEARCH(lookup_table!A:A,C440)), 0) ), "Uncategorized")} -> Dining Out | G440: Card1
A441: 45896 | B441: =TEXT(A441,"yyyy-mm") -> 2025-08 | C441: STATE FARM INSURANCE | D441: 59.86 | E441: Services | F441: {=IFERROR( INDEX(lookup_table!B:B, MATCH(TRUE, ISNUMBER(SEARCH(lookup_table!A:A,C441)), 0) ), "Uncategorized")} -> Bills | G441: Card2
A442: 45896 | B442: =TEXT(A442,"yyyy-mm") -> 2025-08 | C442: JUANITA'S MEXICAN | D442: 11.91 | E442: Entertainment | F442: {=IFERROR( INDEX(lookup_table!B:B, MATCH(TRUE, ISNUMBER(SEARCH(lookup_table!A:A,C442)), 0) ), "Uncategorized")} -> Dining Out | G442: Card1
A443: 45896 | B443: =TEXT(A443,"yyyy-mm") -> 2025-08 | C443: SOTTO NIGHT CLUB | D443: 5 | E443: Gasoline | F443: {=IFERROR( INDEX(lookup_table!B:B, MATCH(TRUE, ISNUMBER(SEARCH(lookup_table!A:A,C443)), 0) ), "Uncategorized")} -> Dining Out | G443: Card2
A444: 45896 | B444: =TEXT(A444,"yyyy-mm") -> 2025-08 | C444: TRADER JOES | D444: 36.12 | E444: Grocery | F444: {=IFERROR( INDEX(lookup_table!B:B, MATCH(TRUE, ISNUMBER(SEARCH(lookup_table!A:A,C444)), 0) ), "Uncategorized")} -> Groceries | G444: Card1
A445: 45896 | B445: =TEXT(A445,"yyyy-mm") -> 2025-08 | C445: TRADER JOES | D445: 8.27 | E445: Grocery | F445: {=IFERROR( INDEX(lookup_table!B:B, MATCH(TRUE, ISNUMBER(SEARCH(lookup_table!A:A,C445)), 0) ), "Uncategorized")} -> Groceries | G445: Card1
A446: 45896 | B446: =TEXT(A446,"yyyy-mm") -> 2025-08 | C446: SQ *FEIRO MARI 08/27/25 21:23 SQUARE PURCHASE PORT ANGELES WA | D446: 6.5 | E446: Uncategorized | F446: {=IFERROR( INDEX(lookup_table!B:B, MATCH(TRUE, ISNUMBER(SEARCH(lookup_table!A:A,C446)), 0) ), "Uncategorized")} -> Other | G446: Bank2
A447: 45896 | B447: =TEXT(A447,"yyyy-mm") -> 2025-08 | C447: SHOCKBYTE | D447: 2.5 | E447: Other | F447: {=IFERROR( INDEX(lookup_table!B:B, MATCH(TRUE, ISNUMBER(SEARCH(lookup_table!A:A,C447)), 0) ), "Uncategorized")} -> Subscriptions | G447: Card1
A448: 45896 | B448: =TEXT(A448,"yyyy-mm") -> 2025-08 | C448: SHOCKBYTE | D448: 2 | E448: Other | F448: {=IFERROR( INDEX(lookup_table!B:B, MATCH(TRUE, ISNUMBER(SEARCH(lookup_table!A:A,C448)), 0) ), "Uncategorized")} -> Subscriptions | G448: Card1
A449: 45896 | B449: =TEXT(A449,"yyyy-mm") -> 2025-08 | C449: ARCO | D449: 13.37 | E449: Gas | F449: {=IFERROR( INDEX(lookup_table!B:B, MATCH(TRUE, ISNUMBER(SEARCH(lookup_table!A:A,C449)), 0) ), "Uncategorized")} -> Transportation | G449: Card1
... A627: 45989 | B627: =TEXT(A627,"yyyy-mm") -> 2025-11 | C627: WITHDRAWAL | D627: 50 | E627: Cash & ATM | F627: {=IFERROR( INDEX(lookup_table!B:B, MATCH(TRUE, ISNUMBER(SEARCH(lookup_table!A:A,C627)), 0) ), "Uncategorized")} -> Withdrawal | G627: Bank2
A628: 45990 | B628: =TEXT(A628,"yyyy-mm") -> 2025-11 | C628: COMPASS COFFEE | D628: 5.96 | F628: {=IFERROR( INDEX(lookup_table!B:B, MATCH(TRUE, ISNUMBER(SEARCH(lookup_table!A:A,C628)), 0) ), "Uncategorized")} -> Dining Out | G628: Bank1
A629: 45992 | B629: =TEXT(A629,"yyyy-mm") -> 2025-12 | C629: HUNTINGTON BANKS | D629: 346.3 | F629: {=IFERROR( INDEX(lookup_table!B:B, MATCH(TRUE, ISNUMBER(SEARCH(lookup_table!A:A,C629)), 0) ), "Uncategorized")} -> Bills | G629: Bank1
A630: 45992 | B630: =TEXT(A630,"yyyy-mm") -> 2025-12 | C630: WEST GLACIER MERCANTILE | D630: 14.47 | E630: Merchandise | F630: {=IFERROR( INDEX(lookup_table!B:B, MATCH(TRUE, ISNUMBER(SEARCH(lookup_table!A:A,C630)), 0) ), "Uncategorized")} -> Groceries | G630: Card2
A631: 45992 | B631: =TEXT(A631,"yyyy-mm") -> 2025-12 | C631: FLEET FARM FUEL | D631: 28.35 | E631: Gas | F631: {=IFERROR( INDEX(lookup_table!B:B, MATCH(TRUE, ISNUMBER(SEARCH(lookup_table!A:A,C631)), 0) ), "Uncategorized")} -> Shopping | G631: Card1
A632: 45992 | B632: =TEXT(A632,"yyyy-mm") -> 2025-12 | C632: CONCOURSE HOTEL F&B | D632: 8 | F632: {=IFERROR( INDEX(lookup_table!B:B, MATCH(TRUE, ISNUMBER(SEARCH(lookup_table!A:A,C632)), 0) ), "Uncategorized")} -> Travel | G632: Bank1
A633: 45993 | B633: =TEXT(A633,"yyyy-mm") -> 2025-12 | C633: DAN & LOUIS OYSTER BAR | D633: 43 | E633: Restaurants | F633: {=IFERROR( INDEX(lookup_table!B:B, MATCH(TRUE, ISNUMBER(SEARCH(lookup_table!A:A,C633)), 0) ), "Uncategorized")} -> Dining Out | G633: Card1
A634: 45993 | B634: =TEXT(A634,"yyyy-mm") -> 2025-12 | C634: AUTOZONE | D634: 28.47 | E634: Other | F634: {=IFERROR( INDEX(lookup_table!B:B, MATCH(TRUE, ISNUMBER(SEARCH(lookup_table!A:A,C634)), 0) ), "Uncategorized")} -> Transportation | G634: Card1
A635: 45994 | B635: =TEXT(A635,"yyyy-mm") -> 2025-12 | C635: ACOUSTIC CAFE | D635: 4 | F635: {=IFERROR( INDEX(lookup_table!B:B, MATCH(TRUE, ISNUMBER(SEARCH(lookup_table!A:A,C635)), 0) ), "Uncategorized")} -> Dining Out | G635: Bank1
A636: 45994 | B636: =TEXT(A636,"yyyy-mm") -> 2025-12 | C636: EAU CLAIRE WI CITATION | D636: 33.95 | E636: Other | F636: {=IFERROR( INDEX(lookup_table!B:B, MATCH(TRUE, ISNUMBER(SEARCH(lookup_table!A:A,C636)), 0) ), "Uncategorized")} -> Transportation | G636: Card1
A637: 45997 | B637: =TEXT(A637,"yyyy-mm") -> 2025-12 | C637: MICHELANGELO'S COFFEEHOUSE | D637: 10.85 | E637: Grocery | F637: {=IFERROR( INDEX(lookup_table!B:B, MATCH(TRUE, ISNUMBER(SEARCH(lookup_table!A:A,C637)), 0) ), "Uncategorized")} -> Dining Out | G637: Card1
A638: 45997 | B638: =TEXT(A638,"yyyy-mm") -> 2025-12 | C638: 360TRAINING.COM | D638: 15.77 | F638: {=IFERROR( INDEX(lookup_table!B:B, MATCH(TRUE, ISNUMBER(SEARCH(lookup_table!A:A,C638)), 0) ), "Uncategorized")} -> Subscriptions | G638: Bank1
A639: 45998 | B639: =TEXT(A639,"yyyy-mm") -> 2025-12 | C639: CULVERS | D639: 9.17 | E639: Restaurants | F639: {=IFERROR( INDEX(lookup_table!B:B, MATCH(TRUE, ISNUMBER(SEARCH(lookup_table!A:A,C639)), 0) ), "Uncategorized")} -> Dining Out | G639: Card1
...

Sheet monthly_summary
V1: =IFERROR(__xludf.DUMMYFUNCTION("QUERY(raw_data!B:E, ""select C, sum(D) where C is not null group by C order by sum(D) desc limit 11 label C 'Merchant', sum(D) 'Total Spent'"")"),"Merchant") -> Merchant | W1: =IFERROR(__xludf.DUMMYFUNCTION("""COMPUTED_VALUE"""),"Total Spent") -> Total Spent
V2: =IFERROR(__xludf.DUMMYFUNCTION("""COMPUTED_VALUE"""),"STEVE BROWN APARTMENTS") -> STEVE BROWN APARTMENTS | W2: =IFERROR(__xludf.DUMMYFUNCTION("""COMPUTED_VALUE"""),5235.0) -> 5235
V3: =IFERROR(__xludf.DUMMYFUNCTION("""COMPUTED_VALUE"""),"HUNTINGTON BANKS") -> HUNTINGTON BANKS | W3: =IFERROR(__xludf.DUMMYFUNCTION("""COMPUTED_VALUE"""),4876.9000000000015) -> 4876.9
V4: =IFERROR(__xludf.DUMMYFUNCTION("""COMPUTED_VALUE"""),"MADISON GAS & ELECTRIC") -> MADISON GAS & ELECTRIC | W4: =IFERROR(__xludf.DUMMYFUNCTION("""COMPUTED_VALUE"""),1102.84) -> 1102.84
V5: =IFERROR(__xludf.DUMMYFUNCTION("""COMPUTED_VALUE"""),"KWIK TRIP") -> KWIK TRIP | W5: =IFERROR(__xludf.DUMMYFUNCTION("""COMPUTED_VALUE"""),999.4600000000003) -> 999.46
V6: =IFERROR(__xludf.DUMMYFUNCTION("""COMPUTED_VALUE"""),"GRAHAMS AUTO & TRUCK") -> GRAHAMS AUTO & TRUCK | W6: =IFERROR(__xludf.DUMMYFUNCTION("""COMPUTED_VALUE"""),825.15) -> 825.15
V7: =IFERROR(__xludf.DUMMYFUNCTION("""COMPUTED_VALUE"""),"WOODMANS FOOD MARKET") -> WOODMANS FOOD MARKET | W7: =IFERROR(__xludf.DUMMYFUNCTION("""COMPUTED_VALUE"""),773.5800000000002) -> 773.58
V8: =IFERROR(__xludf.DUMMYFUNCTION("""COMPUTED_VALUE"""),"GAMERS LIBRARY") -> GAMERS LIBRARY | W8: =IFERROR(__xludf.DUMMYFUNCTION("""COMPUTED_VALUE"""),663.1500000000001) -> 663.15
V9: =IFERROR(__xludf.DUMMYFUNCTION("""COMPUTED_VALUE"""),"AMERICAN FUNDS") -> AMERICAN FUNDS | W9: =IFERROR(__xludf.DUMMYFUNCTION("""COMPUTED_VALUE"""),600.0) -> 600
V10: =IFERROR(__xludf.DUMMYFUNCTION("""COMPUTED_VALUE"""),"STATE FARM INSURANCE") -> STATE FARM INSURANCE | W10: =IFERROR(__xludf.DUMMYFUNCTION("""COMPUTED_VALUE"""),487.78000000000003) -> 487.78
V11: =IFERROR(__xludf.DUMMYFUNCTION("""COMPUTED_VALUE"""),"ALDI") -> ALDI | W11: =IFERROR(__xludf.DUMMYFUNCTION("""COMPUTED_VALUE"""),479.89) -> 479.89
V12: =IFERROR(__xludf.DUMMYFUNCTION("""COMPUTED_VALUE"""),"JIFFY LUBE") -> JIFFY LUBE | W12: =IFERROR(__xludf.DUMMYFUNCTION("""COMPUTED_VALUE"""),469.19000000000005) -> 469.19

Sheet lookup_table
A1: Keyword | B1: Category
A2: american funds | B2: Bills
A3: gas & electric | B3: Bills
A4: huntington | B4: Bills
A5: state farm | B5: Bills
A6: steve brown apartments | B6: Bills
A7: usps | B7: Bills
A8: acoustic | B8: Dining Out
A9: brewing | B9: Dining Out
A10: burger | B10: Dining Out
A11: cafe | B11: Dining Out
A12: caribou coffee | B12: Dining Out
... A165: shockbyte | B165: Subscriptions
A166: 76 | B166: Transportation
A167: amanda park | B167: Transportation
A168: amoco | B168: Transportation
A169: arco | B169: Transportation
A170: auto & truck | B170: Transportation
A171: autozone | B171: Transportation
A172: bp | B172: Transportation
A173: casey | B173: Transportation
A174: cc94 | B174: Transportation
A175: cenex | B175: Transportation
A176: chevron | B176: Transportation
A177: circle k | B177: Transportation
A178: citation | B178: Transportation
... A256: withdrawal | B256: Withdrawal

Sheet categories
A1: my_category | B1: description | C1: budget_monthly
A2: Groceries | B2: Supermarkets, food stores | C2: =400 -> 400
A3: Dining Out | B3: Restaurants, bars, coffee | C3: =300 -> 300
A4: Transportation | B4: Gas, Uber, parking, car payment, insurance | C4: =346.6+100+58+200 -> 704.6
A5: Subscriptions | B5: Netflix, Spotify, gym | C5: =30 -> 30
A6: Travel | B6: Doctors, pharmacy, insurance | C6: =0 -> 0
A7: Bills | B7: Rent, utilities, insurance | C7: =595+25+30+60+7.75 -> 717.75
A8: Entertainment | B8: Movies, concerts, hobbies | C8: =200 -> 200
A9: Shopping | B9: Clothing, Amazon, misc | C9: =100 -> 100
A10: Withdrawl | B10: ATM | C10: ---
A11: Other | B11: Everything else | C11: =100 -> 100

Sheet dashboard
